Workbook

Sheet O'qing
A1: SPS — real ma'lumotlar bazasi (katalog uchun)
A3: Manbalar
A4: 1) Archive.zip — SPS ning eski katalogi (ruscha): 68 ta qolip, har biri uchun o'lcham, 1 m² ga dona, qolip vazni, 1 m² jami vazn, material; fasad termopanel katalogi.
A5: 2) sps_info.zip — menejer bilan birga yozilgan qo'lyozma: kitobcha №1–№108 (dona, kg, chuqurlik, nomlar) va fasad qoliplari varaqlari (DSC raqami bo'yicha nom, o'lcham, ABS / PP vazni).
A6: 3) Qolip suratlari — 264 ta fonsiz surat (DSC03147–DSC03470); modelga bog'lanishi men tomondan taxmin qilingan.
A8: Varaqlar
A9: 1 Archive qoliplar — eski katalogdagi 68 ta model, har bir qolip (A / B / V) alohida qatorda. Vazn hisobi formula bilan tekshirilgan.
A10: 2 Kitobcha (menejer) — №1–№108, qo'lyozma izohlar bilan.
A11: 3 Fasad qoliplari — menejer varaqlaridagi nomlar, o'lchamlar, ABS / PP vaznlari.
A12: 4 Solishtirish — ikkala manbada bor modellar: eski katalog va menejer raqamlari yonma-yon, farqi bilan.
A13: 5 Surat-model — har bir suratning (DSC) qaysi modelga tegishli ekani va ishonch darajasi.
A14: 6 SPS PLAST termopanel — eski fasad katalogidagi 76 ta mahsulot (kod, nom, o'lcham).
... A28: Ikkala manba farq qilgan joyda katalogga qaysi raqam kirishini siz hal qilasiz; hozircha kelishuv — menejer yozgani asosiy.

Sheet 1 Archive qoliplar
A1: Eski katalog (Archive.zip) — 68 ta model, qoliplar bo'yicha
A2: Manba: Archive.zip, eski katalog sahifalari ("Размеры и количество в 1м²", "Материал формы", "Общий вес 1м²"). Raqamlar katalogda yozilganidek.
A3: № (sps_old) | B3: Model | C3: Sarlavhadagi o'lcham | D3: Bo'lim | E3: Qolip | F3: Shakli | G3: Uzunlik, mm | H3: Kenglik, mm | I3: Chuqurlik (balandlik), mm | J3: Katalogda yozilgan son, dona | K3: Qolipdagi katak soni | L3: 1 m² ga qolip soni | M3: Bitta qolip vazni, g | N3: Shu qolip bo'yicha jami, g | O3: Material | P3: Katalogdagi jami vazn 1 m², g | Q3: Hisoblangan jami, g | R3: Farq, g | S3: Hisob holati | T3: 1 m² jami, kg | U3: Izoh
A4: 1 | B4: Monako | C4: 30×30 | D4: Yakka kvadrat | E4: A | F4: kvadrat | G4: 300 | H4: 300 | I4: 30 | J4: 11 | K4: 1 | L4: 11 | M4: 320 | N4: =L4*M4 -> 3520 | O4: Polipropilen / ABS | P4: 3520 | Q4: =SUMIF($A$4:$A$114,A4,$N$4:$N$114) -> 3520 | R4: =P4-Q4 -> 0 | S4: =IF(ABS(R4)<=0.02*P4,"mos","MOS EMAS") -> mos | T4: =P4/1000 -> 3.52
A5: 2 | B5: Ornament 30×30 | C5: 30×30 | D5: Yakka kvadrat | E5: A | F5: kvadrat | G5: 300 | H5: 300 | I5: 30 | J5: 11 | K5: 1 | L5: 11 | M5: 385 | N5: =L5*M5 -> 4235 | O5: Polipropilen / ABS | P5: 4235 | Q5: =SUMIF($A$4:$A$114,A5,$N$4:$N$114) -> 4235 | R5: =P5-Q5 -> 0 | S5: =IF(ABS(R5)<=0.02*P5,"mos","MOS EMAS") -> mos | T5: =P5/1000 -> 4.235
A6: 3 | B6: Yalta | C6: 30×30 | D6: Yakka kvadrat | E6: A | F6: kvadrat | G6: 300 | H6: 300 | I6: 30 | J6: 11 | K6: 1 | L6: 11 | M6: 330 | N6: =L6*M6 -> 3630 | O6: Polipropilen / ABS | P6: 3630 | Q6: =SUMIF($A$4:$A$114,A6,$N$4:$N$114) -> 3630 | R6: =P6-Q6 -> 0 | S6: =IF(ABS(R6)<=0.02*P6,"mos","MOS EMAS") -> mos | T6: =P6/1000 -> 3.63
A7: 4 | B7: Tsvetok | C7: 30×30 | D7: Yakka kvadrat | E7: A | F7: kvadrat | G7: 300 | H7: 300 | I7: 30 | J7: 11 | K7: 1 | L7: 11 | M7: 370 | N7: =L7*M7 -> 4070 | O7: Polipropilen / ABS | P7: 4070 | Q7: =SUMIF($A$4:$A$114,A7,$N$4:$N$114) -> 4070 | R7: =P7-Q7 -> 0 | S7: =IF(ABS(R7)<=0.02*P7,"mos","MOS EMAS") -> mos | T7: =P7/1000 -> 4.07
A8: 5 | B8: Magna | C8: 30×30 | D8: Yakka kvadrat | E8: A | F8: kvadrat | G8: 300 | H8: 300 | I8: 30 | J8: 11 | K8: 1 | L8: 11 | M8: 340 | N8: =L8*M8 -> 3740 | O8: Polipropilen / ABS | P8: 3740 | Q8: =SUMIF($A$4:$A$114,A8,$N$4:$N$114) -> 3740 | R8: =P8-Q8 -> 0 | S8: =IF(ABS(R8)<=0.02*P8,"mos","MOS EMAS") -> mos | T8: =P8/1000 -> 3.74
A9: 6 | B9: Azara | C9: 30×30 | D9: Yakka kvadrat | E9: A | F9: kvadrat | G9: 300 | H9: 300 | I9: 30 | J9: 11 | K9: 1 | L9: 11 | M9: 340 | N9: =L9*M9 -> 3740 | O9: Polipropilen / ABS | P9: 3740 | Q9: =SUMIF($A$4:$A$114,A9,$N$4:$N$114) -> 3740 | R9: =P9-Q9 -> 0 | S9: =IF(ABS(R9)<=0.02*P9,"mos","MOS EMAS") -> mos | T9: =P9/1000 -> 3.74
A10: 7 | B10: Parus 30×30 | C10: 30×30 | D10: Yakka kvadrat | E10: A | F10: kvadrat | G10: 300 | H10: 300 | I10: 30 | J10: 11 | K10: 1 | L10: 11 | M10: 375 | N10: =L10*M10 -> 4125 | O10: Polipropilen / ABS | P10: 4125 | Q10: =SUMIF($A$4:$A$114,A10,$N$4:$N$114) -> 4125 | R10: =P10-Q10 -> 0 | S10: =IF(ABS(R10)<=0.02*P10,"mos","MOS EMAS") -> mos | T10: =P10/1000 -> 4.125
A11: 8 | B11: Travertino | C11: 30×30 | D11: Yakka kvadrat | E11: A | F11: kvadrat | G11: 300 | H11: 300 | I11: 30 | J11: 11 | K11: 1 | L11: 11 | M11: 385 | N11: =L11*M11 -> 4235 | O11: Polipropilen / ABS | P11: 4235 | Q11: =SUMIF($A$4:$A$114,A11,$N$4:$N$114) -> 4235 | R11: =P11-Q11 -> 0 | S11: =IF(ABS(R11)<=0.02*P11,"mos","MOS EMAS") -> mos | T11: =P11/1000 -> 4.235
A12: 9 | B12: Versache 1 | C12: 30×30 | D12: Yakka kvadrat | E12: A | F12: kvadrat | G12: 300 | H12: 300 | I12: 30 | J12: 11 | K12: 1 | L12: 11 | M12: 360 | N12: =L12*M12 -> 3960 | O12: Polipropilen / ABS | P12: 3960 | Q12: =SUMIF($A$4:$A$114,A12,$N$4:$N$114) -> 3960 | R12: =P12-Q12 -> 0 | S12: =IF(ABS(R12)<=0.02*P12,"mos","MOS EMAS") -> mos | T12: =P12/1000 -> 3.96
A13: 10 | B13: Kaliforniya | C13: 30×30 | D13: Yakka kvadrat | E13: A | F13: kvadrat | G13: 300 | H13: 300 | I13: 30 | J13: 11 | K13: 1 | L13: 11 | M13: 375 | N13: =L13*M13 -> 4125 | O13: Polipropilen / ABS | P13: 4125 | Q13: =SUMIF($A$4:$A$114,A13,$N$4:$N$114) -> 4125 | R13: =P13-Q13 -> 0 | S13: =IF(ABS(R13)<=0.02*P13,"mos","MOS EMAS") -> mos | T13: =P13/1000 -> 4.125
A14: 11 | B14: Zanjir | C14: 30×30 | D14: Yakka kvadrat | E14: A | F14: kvadrat | G14: 300 | H14: 300 | I14: 30 | J14: 11 | K14: 1 | L14: 11 | M14: 320 | N14: =L14*M14 -> 3520 | O14: Polipropilen / ABS | P14: 3520 | Q14: =SUMIF($A$4:$A$114,A14,$N$4:$N$114) -> 3520 | R14: =P14-Q14 -> 0 | S14: =IF(ABS(R14)<=0.02*P14,"mos","MOS EMAS") -> mos | T14: =P14/1000 -> 3.52
A15: 12 | B15: Polosa | C15: 30×30 | D15: Yakka kvadrat | E15: A | F15: kvadrat | G15: 300 | H15: 300 | I15: 30 | J15: 11 | K15: 1 | L15: 11 | M15: 330 | N15: =L15*M15 -> 3630 | O15: Polipropilen / ABS | P15: 3630 | Q15: =SUMIF($A$4:$A$114,A15,$N$4:$N$114) -> 3630 | R15: =P15-Q15 -> 0 | S15: =IF(ABS(R15)<=0.02*P15,"mos","MOS EMAS") -> mos | T15: =P15/1000 -> 3.63
... A25: 22 | B25: Uzor 4 gul | C25: 40×40 | D25: Yakka kvadrat | E25: A | F25: kvadrat, 4 gul | G25: 400 | H25: 400 | I25: 45 | J25: 6.25 | K25: 1 | L25: 6.25 | M25: 930 | N25: =L25*M25 -> 5812.5 | O25: Polipropilen / ABS | P25: 5810 | Q25: =SUMIF($A$4:$A$114,A25,$N$4:$N$114) -> 5812.5 | R25: =P25-Q25 -> -2.5 | S25: =IF(ABS(R25)<=0.02*P25,"mos","MOS EMAS") -> mos | T25: =P25/1000 -> 5.81
A26: 23 | B26: Kabanchik 10×10 (kitayskiy) | C26: 10×10 | D26: Yakka (4 katakli) | E26: A | F26: 4 katakli kvadrat | G26: 100 | H26: 100 | I26: 10 | J26: 92 | K26: 4 | L26: =J26/K26 -> 23 | M26: 210 | N26: =L26*M26 -> 4830 | O26: Polipropilen / ABS | P26: 4830 | Q26: =SUMIF($A$4:$A$114,A26,$N$4:$N$114) -> 4830 | R26: =P26-Q26 -> 0 | S26: =IF(ABS(R26)<=0.02*P26,"mos","MOS EMAS") -> mos | T26: =P26/1000 -> 4.83
A27: 24 | B27: Guruch | C27: 20×20 ×4 | D27: Asosiy + kichik kvadrat | E27: A | F27: sakkiz qirra / burchagi kesilgan | G27: 200 | H27: 200 | I27: 20 | J27: 25 | K27: 1 | L27: 25 | M27: 160 | N27: =L27*M27 -> 4000 | O27: Polipropilen / ABS | P27: 4625 | Q27: =SUMIF($A$4:$A$114,A27,$N$4:$N$114) -> 4624 | R27: =P27-Q27 -> 1 | S27: =IF(ABS(R27)<=0.02*P27,"mos","MOS EMAS") -> mos | T27: =P27/1000 -> 4.625
A28: 24 | B28: Guruch | C28: 20×20 ×4 | D28: Asosiy + kichik kvadrat | E28: B | F28: kichik kvadrat (6 katakli) | G28: 53 | H28: 53 | I28: 25 | J28: 4.16 | K28: 6 | L28: 4.16 | M28: 150 | N28: =L28*M28 -> 624 | O28: Polipropilen / ABS
A29: 25 | B29: Bodom | C29: 20×20 ×4 | D29: Asosiy + kichik kvadrat | E29: A | F29: sakkiz qirra / burchagi kesilgan | G29: 200 | H29: 200 | I29: 25 | J29: 25 | K29: 1 | L29: 25 | M29: 145 | N29: =L29*M29 -> 3625 | O29: Polipropilen / ABS | P29: 4250 | Q29: =SUMIF($A$4:$A$114,A29,$N$4:$N$114) -> 4249 | R29: =P29-Q29 -> 1 | S29: =IF(ABS(R29)<=0.02*P29,"mos","MOS EMAS") -> mos | T29: =P29/1000 -> 4.25
A30: 25 | B30: Bodom | C30: 20×20 ×4 | D30: Asosiy + kichik kvadrat | E30: B | F30: kichik kvadrat (6 katakli) | G30: 53 | H30: 53 | I30: 25 | J30: 4.16 | K30: 6 | L30: 4.16 | M30: 150 | N30: =L30*M30 -> 624 | O30: Polipropilen / ABS
A31: 26 | B31: Astana | C31: 30×30 ×4 | D31: Asosiy + kichik kvadrat | E31: A | F31: sakkiz qirra / burchagi kesilgan | G31: 200 | H31: 200 | I31: 25 | J31: 25 | K31: 1 | L31: 25 | M31: 330 | N31: =L31*M31 -> 8250 | O31: Polipropilen / ABS | P31: 4375 | Q31: =SUMIF($A$4:$A$114,A31,$N$4:$N$114) -> 8874 | R31: =P31-Q31 -> -4499 | S31: =IF(ABS(R31)<=0.02*P31,"mos","MOS EMAS") -> MOS EMAS | T31: =P31/1000 -> 4.375 | U31: Sarlavhada 30×30, lekin o'lcham 200×200 va 25 dona deb yozilgan
A32: 26 | B32: Astana | C32: 30×30 ×4 | D32: Asosiy + kichik kvadrat | E32: B | F32: kichik kvadrat (6 katakli) | G32: 53 | H32: 53 | I32: 25 | J32: 4.16 | K32: 6 | L32: 4.16 | M32: 150 | N32: =L32*M32 -> 624 | O32: Polipropilen / ABS
A33: 27 | B33: Yulduz | C33: 30×30 ×4 | D33: Asosiy + kichik kvadrat | E33: A | F33: sakkiz qirra / burchagi kesilgan | G33: 200 | H33: 200 | I33: 25 | J33: 25 | K33: 1 | L33: 25 | M33: 330 | N33: =L33*M33 -> 8250 | O33: Polipropilen / ABS | P33: 4675 | Q33: =SUMIF($A$4:$A$114,A33,$N$4:$N$114) -> 8562 | R33: =P33-Q33 -> -3887 | S33: =IF(ABS(R33)<=0.02*P33,"mos","MOS EMAS") -> MOS EMAS | T33: =P33/1000 -> 4.675 | U33: Sarlavhada 30×30, lekin o'lcham 200×200 va 25 dona deb yozilgan
A34: 27 | B34: Yulduz | C34: 30×30 ×4 | D34: Asosiy + kichik kvadrat | E34: B | F34: kichik kvadrat (6 katakli) | G34: 53 | H34: 53 | I34: 25 | J34: 2.08 | K34: 6 | L34: 2.08 | M34: 150 | N34: =L34*M34 -> 312 | O34: Polipropilen / ABS
A35: 28 | B35: Turkman guli | C35: 30×30 ×4 | D35: Asosiy + kichik kvadrat | E35: A | F35: sakkiz qirra / burchagi kesilgan | G35: 298 | H35: 298 | I35: 38 | J35: 25 | K35: 1 | L35: 25 | M35: 310 | N35: =L35*M35 -> 7750 | O35: Polipropilen / ABS | P35: 4625 | Q35: =SUMIF($A$4:$A$114,A35,$N$4:$N$114) -> 8374 | R35: =P35-Q35 -> -3749 | S35: =IF(ABS(R35)<=0.02*P35,"mos","MOS EMAS") -> MOS EMAS | T35: =P35/1000 -> 4.625 | U35: O'lcham 298×298, lekin 25 dona deb yozilgan (30×30 uchun 11 bo'lishi kerak)
A36: 28 | B36: Turkman guli | C36: 30×30 ×4 | D36: Asosiy + kichik kvadrat | E36: B | F36: kichik kvadrat (6 katakli) | G36: 72 | H36: 72 | I36: 30 | J36: 4.16 | K36: 6 | L36: 4.16 | M36: 150 | N36: =L36*M36 -> 624 | O36: Polipropilen / ABS
A37: 29 | B37: Eksklyuziv | C37: 30×30 ×4 | D37: Asosiy + kichik kvadrat | E37: A | F37: sakkiz qirra / burchagi kesilgan | G37: 200 | H37: 200 | I37: 25 | J37: 25 | K37: 1 | L37: 25 | M37: 330 | N37: =L37*M37 -> 8250 | O37: Polipropilen / ABS | P37: 4250 | Q37: =SUMIF($A$4:$A$114,A37,$N$4:$N$114) -> 8874 | R37: =P37-Q37 -> -4624 | S37: =IF(ABS(R37)<=0.02*P37,"mos","MOS EMAS") -> MOS EMAS | T37: =P37/1000 -> 4.25 | U37: Sarlavhada 30×30, lekin o'lcham 200×200 va 25 dona deb yozilgan
A38: 29 | B38: Eksklyuziv | C38: 30×30 ×4 | D38: Asosiy + kichik kvadrat | E38: B | F38: kichik kvadrat (6 katakli) | G38: 53 | H38: 53 | I38: 25 | J38: 4.16 | K38: 6 | L38: 4.16 | M38: 150 | N38: =L38*M38 -> 624 | O38: Polipropilen / ABS
A39: 30 | B39: Tomir | C39: 20×20 ×2 | D39: Asosiy + kichik kvadrat | E39: A | F39: sakkiz qirra / burchagi kesilgan | G39: 200 | H39: 200 | I39: 25 | J39: 25 | K39: 1 | L39: 25 | M39: 175 | N39: =L39*M39 -> 4375 | O39: Polipropilen / ABS | P39: 4675 | Q39: =SUMIF($A$4:$A$114,A39,$N$4:$N$114) -> 4687 | R39: =P39-Q39 -> -12 | S39: =IF(ABS(R39)<=0.02*P39,"mos","MOS EMAS") -> mos | T39: =P39/1000 -> 4.675
A40: 30 | B40: Tomir | C40: 20×20 ×2 | D40: Asosiy + kichik kvadrat | E40: B | F40: kichik kvadrat (6 katakli) | G40: 53 | H40: 53 | I40: 25 | J40: 2.08 | K40: 6 | L40: 2.08 | M40: 150 | N40: =L40*M40 -> 312 | O40: Polipropilen / ABS
A41: 31 | B41: Mozaika | C41: 20×20 ×2 | D41: Asosiy + kichik kvadrat | E41: A | F41: sakkiz qirra / burchagi kesilgan | G41: 200 | H41: 200 | I41: 25 | J41: 25 | K41: 1 | L41: 25 | M41: 200 | N41: =L41*M41 -> 5000 | O41: Polipropilen / ABS | P41: 5300 | Q41: =SUMIF($A$4:$A$114,A41,$N$4:$N$114) -> 5312 | R41: =P41-Q41 -> -12 | S41: =IF(ABS(R41)<=0.02*P41,"mos","MOS EMAS") -> mos | T41: =P41/1000 -> 5.3
A42: 31 | B42: Mozaika | C42: 20×20 ×2 | D42: Asosiy + kichik kvadrat | E42: B | F42: kichik kvadrat (6 katakli) | G42: 53 | H42: 53 | I42: 25 | J42: 2.08 | K42: 6 | L42: 2.08 | M42: 150 | N42: =L42*M42 -> 312 | O42: Polipropilen / ABS
A43: 32 | B43: Novvot | C43: 20×20 ×2 | D43: Asosiy + kichik kvadrat | E43: A | F43: sakkiz qirra / burchagi kesilgan | G43: 200 | H43: 200 | I43: 25 | J43: 25 | K43: 1 | L43: 25 | M43: 175 | N43: =L43*M43 -> 4375 | O43: Polipropilen / ABS | P43: 4675 | Q43: =SUMIF($A$4:$A$114,A43,$N$4:$N$114) -> 4687 | R43: =P43-Q43 -> -12 | S43: =IF(ABS(R43)<=0.02*P43,"mos","MOS EMAS") -> mos | T43: =P43/1000 -> 4.675
A44: 32 | B44: Novvot | C44: 20×20 ×2 | D44: Asosiy + kichik kvadrat | E44: B | F44: kichik kvadrat (6 katakli) | G44: 53 | H44: 53 | I44: 25 | J44: 2.08 | K44: 6 | L44: 2.08 | M44: 150 | N44: =L44*M44 -> 312 | O44: Polipropilen / ABS
A45: 33 | B45: Uzor 20×20 | C45: 20×20 ×2 | D45: Asosiy + kichik kvadrat | E45: A | F45: sakkiz qirra / burchagi kesilgan | G45: 200 | H45: 200 | I45: 25 | J45: 25 | K45: 1 | L45: 25 | M45: 195 | N45: =L45*M45 -> 4875 | O45: Polipropilen / ABS | P45: 5175 | Q45: =SUMIF($A$4:$A$114,A45,$N$4:$N$114) -> 5187 | R45: =P45-Q45 -> -12 | S45: =IF(ABS(R45)<=0.02*P45,"mos","MOS EMAS") -> mos | T45: =P45/1000 -> 5.175
A46: 33 | B46: Uzor 20×20 | C46: 20×20 ×2 | D46: Asosiy + kichik kvadrat | E46: B | F46: kichik kvadrat (6 katakli) | G46: 53 | H46: 53 | I46: 25 | J46: 2.08 | K46: 6 | L46: 2.08 | M46: 150 | N46: =L46*M46 -> 312 | O46: Polipropilen / ABS
A47: 34 | B47: Parket 20×20 | C47: 20×20 ×2 | D47: Asosiy + kichik kvadrat | E47: A | F47: sakkiz qirra / burchagi kesilgan | G47: 200 | H47: 200 | I47: 25 | J47: 25 | K47: 1 | L47: 25 | M47: 180 | N47: =L47*M47 -> 4500 | O47: Polipropilen / ABS | P47: 4800 | Q47: =SUMIF($A$4:$A$114,A47,$N$4:$N$114) -> 4812 | R47: =P47-Q47 -> -12 | S47: =IF(ABS(R47)<=0.02*P47,"mos","MOS EMAS") -> mos | T47: =P47/1000 -> 4.8
A48: 34 | B48: Parket 20×20 | C48: 20×20 ×2 | D48: Asosiy + kichik kvadrat | E48: B | F48: kichik kvadrat (6 katakli) | G48: 53 | H48: 53 | I48: 25 | J48: 2.08 | K48: 6 | L48: 2.08 | M48: 150 | N48: =L48*M48 -> 312 | O48: Polipropilen / ABS
A49: 35 | B49: Bodom | C49: 20×20 ×2 | D49: Asosiy + kichik kvadrat | E49: A | F49: sakkiz qirra / burchagi kesilgan | G49: 200 | H49: 200 | I49: 25 | J49: 25 | K49: 1 | L49: 25 | M49: 175 | N49: =L49*M49 -> 4375 | O49: Polipropilen / ABS | P49: 4675 | Q49: =SUMIF($A$4:$A$114,A49,$N$4:$N$114) -> 4687 | R49: =P49-Q49 -> -12 | S49: =IF(ABS(R49)<=0.02*P49,"mos","MOS EMAS") -> mos | T49: =P49/1000 -> 4.675
...

Sheet 2 Kitobcha (menejer)
A1: Kitobcha №1–№108 — menejer qo'lyozmasi
A2: Manba: sps_info.zip, kitobcha betlari (3–30). Ko'k ruchka bilan yozilgan izohlar ko'chirilgan; (?) — aniq o'qilmagan.
A3: № | B3: Bet | C3: Bosma nomi | D3: Qo'lda yozilgan nom | E3: Bosma o'lcham, sm | F3: Chuqurlik, sm | G3: Qoliplar | H3: 1 m² ga dona (qoliplar bo'yicha) | I3: 1 m² ga kg | J3: Sheriklik izohi | K3: Boshqa izoh | L3: Holat
A4: 1 | B4: 3 | C4: (nomsiz) | D4: Uzor | E4: 50×25 | F4: 5.5 | G4: 1 qolip | H4: 8 | I4: 6 | K4: Nomi egasi tomonidan tasdiqlandi | L4: aniq
A5: 2 | B5: 3 | C5: (nomsiz) | D5: Polasa | E5: 30×30 | F5: 3 | G5: 1 qolip | H5: 11 | I5: 3.6 | L5: aniq
A6: 3 | B6: 3 | C6: (nomsiz) | E6: 30×30 | F6: 3 | G6: 1 qolip | L6: hozir yo'q — katalogga kirmaydi
A7: 4 | B7: 3 | C7: Eksklyuziv | E7: 40×40 | F7: 4.5 | G7: 1 qolip (4 gul) | H7: 6,25 | I7: 5.5 | L7: aniq
A8: 5 | B8: 4 | C8: Uzor | E8: 30×30 | F8: 3 | G8: 1 qolip | H8: 11 | I8: 3.8 | L8: aniq
A9: 6 | B9: 4 | C9: Kabanchik | E9: 15×15 / 5×5 | G9: 2 katakli + kubik (6 katakli) | H9: sherik bilan 40; sheriksiz 44 | I9: 5.9 | J9: Sherik bilan 40 dona = 5,9 kg; sheriksiz 44 dona = 5,2 kg | L9: aniq
A10: 7 | B10: 4 | C10: Mumtoz | G10: 2 katakli + cho'ziq sakkiz qirra | H10: 11 + 11 | I10: 5 | J10: Juft | L10: aniq
A11: 8 | B11: 4 | C11: Florensiya | E11: 20×20 | F11: 3 | G11: 1 qolip (sakkiz qirra) | H11: 25 | I11: 4.6 | J11: Sherigi yo'q — o'zi alohida teriladi | K11: Egasi tomonidan tasdiqlandi | L11: aniq
A12: 9 | B12: 5 | C12: Sultan 2 | E12: 20×20 | F12: 3 | G12: asosiy + kubik (6 katakli) | H12: 25 + 6,25 | I12: 4.3 | L12: aniq
A13: 10 | B13: 5 | C13: Sultan | E13: 20×20 | F13: 3 | G13: asosiy + kubik (6 katakli) | H13: 25 + 12,5 | I13: 4.6 | L13: aniq
A14: 11 | B14: 5 | C14: Kobanchik | E14: 20×20 | F14: 3 | G14: kvadrat + kubik (6 katakli) | H14: 23 + 23 | I14: 4.6 | J14: Alohida terilsa 25 ta | L14: aniq
A15: 12 | B15: 5 | C15: Parket | E15: 30×30 | F15: 3 | G15: 1 qolip | L15: hozir yo'q — katalogga kirmaydi
A16: 13 | B16: 6 | C16: Dubay | E16: 42×12 (qo'lda) | F16: 4.5 | G16: 3 katakli | H16: 21 qolip | I16: 6 | K16: "42 uzunligi, 12 eni" | L16: aniq
A17: 14 | B17: 6 | C17: (nomsiz) | G17: katta kvadrat + kichik kvadrat | L17: hozir yo'q — katalogga kirmaydi
A18: 15 | B18: 6 | C18: National | E18: 30×30 / 10×30 / 10×10 | G18: 3 qolip | H18: 6 + 13 + 7 | I18: 5.3 | L18: aniq
A19: 16 | B19: 6 | C19: Parket | E19: 12×36 / 4 o'chirilgan → 15×60 (qo'lda) | G19: 1 qolip | H19: 5,5 (?) | K19: Egasi: ma'lumoti eski katalogda bor — lekin eski katalogda faqat Parket 20×20 ×2 bor; aniqlashtirish kerak | L19: aniqlashtirish kerak
A20: 17 | B20: 7 | K20: 7–8-betlar rasmi yuborilmagan | L20: bet yuborilmagan
A21: 18 | B21: 7 | K21: 7–8-betlar rasmi yuborilmagan | L21: bet yuborilmagan
A22: 19 | B22: 8 | K22: 7–8-betlar rasmi yuborilmagan | L22: bet yuborilmagan
A23: 20 | B23: 8 | K23: 7–8-betlar rasmi yuborilmagan | L23: bet yuborilmagan
A24: 21 | B24: 9 | C24: Kabanchik | E24: 15×15 / 5×5 | G24: kubik (6 katakli) + kvadrat | H24: 40 + 40 | I24: 5.8 | L24: aniq
A25: 22 | B25: 9 | C25: Vetnam | E25: 17,5×17,5 / 5×5 | G25: sakkiz qirra + kubik (6 katakli) | H25: 33 + 33 | I25: 5.3 | L25: aniq
A26: 23 | B26: 9 | C26: Kabanchik | E26: 15×15 / 5×5 | G26: kubik (6 katakli) + 2 katakli | H26: 40 + 40 | I26: 5.8 | L26: aniq
A27: 24 | B27: 9 | C27: Parus | E27: 36×18 / 18×9 | F27: 4 | G27: to'rtburchak + 2 katakli | H27: 13,5 + 13,5 | I27: 5.3 | L27: aniq
A28: 25 | B28: 10 | C28: 3D | E28: 30×30 | F28: 3 | G28: kvadrat + strelka | H28: 6,5 + 13 | I28: 5.2 | L28: aniq
A29: 26 | B29: 10 | C29: 4D | E29: 17,5×17,5 | F29: 3 | G29: kvadrat + olti qirra | H29: 8 + 32 | I29: 5.8 | L29: aniq
A30: 27 | B30: 10 | C30: Vegas | E30: 35×35 / 8×8 / 5×5 | G30: sakkiz qirra + 2 xil kubik | H30: 8,2 + 4,2 + 4,2 | I30: 4.9 | L30: aniq
A31: 28 | B31: 10 | C31: Safir | E31: 14×14 / 5×5 | G31: qo'shaloq sakkiz qirra + kubik | H31: 49 + 49 | I31: 6 | L31: aniq
A32: 29 | B32: 11 | C32: Dubay shershavoe | E32: 42×12 (qo'lda) | F32: 3 | G32: 3 katakli (+ 2 ta trapetsiya qolip chiziq bilan ajratilgan) | H32: 21 | I32: 6 | L32: aniq
A33: 30 | B33: 11 | C33: Dubay | G33: 2 katakli trapetsiya | H33: 45 | I33: 6.2 | L33: aniq
A34: 31 | B34: 11 | C34: Dubay | G34: 3 katakli | H34: 21 | I34: 6 | L34: aniq
A35: 32 | B35: 11 | C35: Dubay gladkiy | G35: 3 katakli | H35: 21 | I35: 6 | K35: Faqat pastdagi 3 katakli qolip — trapetsiya qoliplar kirmaydi (tasdiqlandi) | L35: aniq
A36: 33 | B36: 12 | C36: Farovon | G36: 2 qolip | H36: 15 + 15 | I36: 5.71 | K36: Egasi tomonidan tasdiqlandi | L36: aniq
A37: 34 | B37: 12 | C37: Royal 1 | G37: figurali + arka | H37: 25 + 12,5 | I37: 4.5 | K37: Oldingi raqamlar o'chirib tuzatilgan | L37: aniq
A38: 35 | B38: 12 | C38: Royal 2 | G38: 4 katakli + arka + xoch | H38: 6 + 22 + 6 | I38: 4.2 | L38: aniq
A39: 36 | B39: 12 | C39: Windows | G39: 4 katakli + 2 ta egri | H39: 4 + 15 + 15 | I39: 4.56 | L39: aniq
A40: 37 | B40: 13 | C40: Madrid (o'chirilgan) | D40: Parus | E40: 18×36 / 8×8 | F40: 4 | G40: to'rtburchak + kubik (6 katakli) | H40: 14,5 + 14,5 | I40: 5.3 | L40: aniq
...

Sheet 3 Fasad qoliplari
A1: Fasad va termopanel qoliplari — menejer varaqlari + suratlar
A2: Manba: sps_info.zip dagi 7 varaq (258–273-betlar) va qolip suratlari. Varaq tepasidagi izoh: qoliplar ABS va PP (qora) materialida, vazn har biriga alohida.
A3: Surat (DSC) | B3: Nomi (menejer) | C3: O'lcham, sm | D3: Chuqurlik, sm | E3: 1 m² ga dona | F3: ABS, kg / m² | G3: PP, kg / m² | H3: Izoh | I3: Qo'lyozma holati | J3: Surat holati
A4: DSC03147 | B4: Skameyka (3 forma) | C4: 93 / 80 / 60 | H4: 3 ta qolip: DSC03147, 03149, 03150 | I4: aniq o'qildi
A5: DSC03148 | B5: Skameyka (3 forma) | H5: 3 forma to'plami | I5: —
A6: DSC03149 | B6: Skameyka (3 forma) | H6: 3 forma to'plami | I6: —
A7: DSC03150 | B7: Skameyka (3 forma) | H7: 3 forma to'plami | I7: —
A8: DSC03151 | B8: Fasad Beeline gladkiy | C8: 30×60 | D8: 3 | E8: 5.5 | F8: 4.7 | G8: 3.75 | I8: aniq o'qildi | J8: O'ngda shtativ qisqichi ko'rinadi
A9: DSC03152 | B9: Fasad Beeline gladkiy 30×60 | H9: Oldingi suratning ikkinchi kadri | I9: — | J9: O'ngda shtativ qisqichi ko'rinadi
A10: DSC03153 | B10: Kirpich fasad | C10: 25×50 (3,5 sm, 8 dona) va 30×60 (3 sm, 5,5 dona) | H10: Vaznlar: ABS 5,12 / PP 4,25 va ABS 4,47 / PP 3,65 — qaysi o'lchamga tegishli ekani aniq emas | I10: qayta tekshirilsin | J10: O'ngda shtativ qisqichi ko'rinadi
A11: DSC03154 | B11: Quba fasad | C11: 30×60: 5,5 dona; 25×50: 3 sm, 8 dona | H11: 30×60 — ABS 4,35 / PP 3,7; 25×50 — ABS 4,46 / PP 3,5; yonida "3,5 sm chuqur" | I11: aniq o'qildi | J11: Chapda boshqa qolip bo'lagi qolgan
A12: DSC03155 | B12: Rus 2.2 | C12: 30×60 | D12: 3 | F12: 4.2 | G12: 3.3 | I12: aniq o'qildi | J12: O'ngda shtativ qisqichi ko'rinadi
A13: DSC03156 | B13: Rus 2.2 30×60 | H13: Oldingi suratning ikkinchi kadri | I13: — | J13: O'ngda shtativ qisqichi ko'rinadi
A14: DSC03157 | B14: Yangi Beeline shershaviy | C14: 30×60 | D14: 3 | F14: 4.5 | G14: 3.5 | I14: aniq o'qildi | J14: O'ngda shtativ qisqichi ko'rinadi
A15: DSC03158 | B15: Yangi Beeline shershaviy 30×60 | H15: Oldingi suratning ikkinchi kadri | I15: — | J15: O'ngda shtativ qisqichi ko'rinadi
A16: DSC03159 | B16: Rus 2.2 | I16: aniq o'qildi | J16: O'ngda shtativ qisqichi ko'rinadi
A17: DSC03160 | B17: Rus 2.2 | H17: Oldingi suratning ikkinchi kadri | I17: — | J17: O'ngda shtativ qisqichi ko'rinadi
A18: DSC03161 | B18: Kirpich | I18: aniq o'qildi | J18: O'ngda shtativ qisqichi ko'rinadi
A19: DSC03162 | B19: Kirpich | H19: Oldingi suratning ikkinchi kadri | I19: — | J19: O'ngda shtativ qisqichi ko'rinadi
A20: DSC03163 | B20: Rus 2 | I20: aniq o'qildi | J20: O'ngda shtativ qisqichi ko'rinadi
A21: DSC03164 | B21: Rus 2 | H21: Oldingi suratning ikkinchi kadri | I21: — | J21: O'ngda shtativ qisqichi ko'rinadi
A22: DSC03165 | B22: Beeline №1 | I22: aniq o'qildi | J22: O'ngda shtativ qisqichi ko'rinadi
A23: DSC03166 | B23: Beeline №1 | H23: Oldingi suratning ikkinchi kadri | I23: — | J23: O'ngda shtativ qisqichi ko'rinadi
A24: DSC03167 | B24: Rus 2.2 ABS | I24: aniq o'qildi | J24: O'ngda shtativ qisqichi ko'rinadi
A25: DSC03168 | B25: Rus 2.2 ABS | H25: Oldingi suratning ikkinchi kadri | I25: — | J25: O'ngda shtativ qisqichi ko'rinadi
A26: DSC03169 | B26: Qubba | I26: aniq o'qildi | J26: O'ngda shtativ qisqichi ko'rinadi
A27: DSC03170 | B27: Qubba | H27: Oldingi suratning ikkinchi kadri | I27: — | J27: O'ngda shtativ qisqichi ko'rinadi
A28: DSC03171 | B28: Shershaviy | I28: aniq o'qildi | J28: O'ngda shtativ qisqichi ko'rinadi
A29: DSC03172 | B29: Shershaviy | H29: Oldingi suratning ikkinchi kadri | I29: — | J29: O'ngda shtativ qisqichi ko'rinadi
A30: DSC03174 | B30: Labirint | I30: aniq o'qildi
A31: DSC03175 | B31: Fasad 3D | D31: 3.5 | E31: 8 | F31: 4.6 | G31: 3.4 | I31: aniq o'qildi
A32: DSC03176 | B32: Kirpich | I32: aniq o'qildi
A33: DSC03177 | B33: Rus 3 | I33: aniq o'qildi
A34: DSC03178 | B34: Brilliant | C34: 25×50 | D34: 3.5 | E34: 8 | F34: 4.7 | G34: 3.9 | I34: aniq o'qildi
A35: DSC03179 | B35: Quba | C35: 25×50 | I35: aniq o'qildi
A36: DSC03182 | B36: Rus 2 | I36: aniq o'qildi
A37: DSC03183 | B37: Qubba | I37: aniq o'qildi
A38: DSC03184 | B38: Fasad 3D | I38: aniq o'qildi
A39: DSC03185 | B39: o'qilmadi | H39: "ABC 3,53" deb yozilgan (ABS vazni bo'lishi mumkin) | I39: qayta tekshirilsin
A40: DSC03186 | B40: Labirint | C40: 25×50 | D40: 3.5 | E40: 8 | F40: 4.95 | G40: 3.7 | I40: aniq o'qildi
...

Sheet 4 Solishtirish
A1: Solishtirish — eski katalog va menejer raqamlari
A2: Faqat ikkala manbada ham bor modellar. Eski katalog kg = "1 Archive qoliplar" varag'idagi jami vazn; menejer kg = "2 Kitobcha" varag'i. Farq 0,3 kg dan katta bo'lsa belgilanadi.
A3: Model (eski katalog) | B3: sps_old № | C3: Kitobcha № | D3: Kitobchadagi nomi | E3: Eski katalog: 1 m², kg | F3: Menejer: 1 m², kg | G3: Farq, kg (menejer − eski) | H3: Holat | I3: Eski katalog: dona | J3: Menejer: dona | K3: Izoh
A4: Dubay 40×40 | B4: 21 | C4: 38 | D4: Dubay | E4: ='1 Archive qoliplar'!T24 -> 5.75 | F4: ='2 Kitobcha (menejer)'!I41 -> 5.7 | G4: =IF(F4="","",F4-E4) -> -0.05 | H4: =IF(F4="","menejerda kg yo'q",IF(ABS(G4)>0.3,"farq katta","yaqin")) -> yaqin | I4: 6,25 | J4: 6,25
A5: Uzor 4 gul | B5: 22 | C5: 4 | D5: Eksklyuziv | E5: ='1 Archive qoliplar'!T25 -> 5.81 | F5: ='2 Kitobcha (menejer)'!I7 -> 5.5 | G5: =IF(F5="","",F5-E5) -> -0.31 | H5: =IF(F5="","menejerda kg yo'q",IF(ABS(G5)>0.3,"farq katta","yaqin")) -> farq katta | I5: 6,25 | J5: 6,25
A6: Tsvetok | B6: 4 | C6: 5 | D6: Uzor | E6: ='1 Archive qoliplar'!T7 -> 4.07 | F6: ='2 Kitobcha (menejer)'!I8 -> 3.8 | G6: =IF(F6="","",F6-E6) -> -0.27 | H6: =IF(F6="","menejerda kg yo'q",IF(ABS(G6)>0.3,"farq katta","yaqin")) -> yaqin | I6: 11 | J6: 11
A7: Polosa | B7: 12 | C7: 2 | D7: Polasa | E7: ='1 Archive qoliplar'!T15 -> 3.63 | F7: ='2 Kitobcha (menejer)'!I5 -> 3.6 | G7: =IF(F7="","",F7-E7) -> -0.03 | H7: =IF(F7="","menejerda kg yo'q",IF(ABS(G7)>0.3,"farq katta","yaqin")) -> yaqin | I7: 11 | J7: 11
A8: Zanjir | B8: 11 | C8: 71 | D8: Zanjir | E8: ='1 Archive qoliplar'!T14 -> 3.52 | F8: ='2 Kitobcha (menejer)'!I74 -> 3.5 | G8: =IF(F8="","",F8-E8) -> -0.02 | H8: =IF(F8="","menejerda kg yo'q",IF(ABS(G8)>0.3,"farq katta","yaqin")) -> yaqin | I8: 11
A9: Magna | B9: 5 | C9: 72 | D9: Magna | E9: ='1 Archive qoliplar'!T8 -> 3.74 | G9: =IF(F9="","",F9-E9) | H9: =IF(F9="","menejerda kg yo'q",IF(ABS(G9)>0.3,"farq katta","yaqin")) -> menejerda kg yo'q | I9: 11 | J9: 10,5 + 10,5
A10: Kaliforniya | B10: 10 | C10: 74 | D10: Kaliforniya | E10: ='1 Archive qoliplar'!T13 -> 4.125 | F10: ='2 Kitobcha (menejer)'!I77 -> 3.8 | G10: =IF(F10="","",F10-E10) -> -0.325 | H10: =IF(F10="","menejerda kg yo'q",IF(ABS(G10)>0.3,"farq katta","yaqin")) -> farq katta | I10: 11 | J10: 11
A11: Versache 1 | B11: 9 | C11: 75 | D11: Versachi | E11: ='1 Archive qoliplar'!T12 -> 3.96 | F11: ='2 Kitobcha (menejer)'!I78 -> 3.6 | G11: =IF(F11="","",F11-E11) -> -0.36 | H11: =IF(F11="","menejerda kg yo'q",IF(ABS(G11)>0.3,"farq katta","yaqin")) -> farq katta | I11: 11 | J11: 11
A12: Strelka | B12: 20 | C12: 76 | D12: Plyus | E12: ='1 Archive qoliplar'!T23 -> 4.675 | F12: ='2 Kitobcha (menejer)'!I79 -> 4.6 | G12: =IF(F12="","",F12-E12) -> -0.075 | H12: =IF(F12="","menejerda kg yo'q",IF(ABS(G12)>0.3,"farq katta","yaqin")) -> yaqin | I12: 11 | J12: 11
A13: Setka | B13: 14 | C13: 77 | D13: Setka | E13: ='1 Archive qoliplar'!T17 -> 4.125 | F13: ='2 Kitobcha (menejer)'!I80 -> 4.1 | G13: =IF(F13="","",F13-E13) -> -0.025 | H13: =IF(F13="","menejerda kg yo'q",IF(ABS(G13)>0.3,"farq katta","yaqin")) -> yaqin | I13: 11 | J13: 11
A14: Parus 30×30 | B14: 7 | C14: 78 | D14: Volna | E14: ='1 Archive qoliplar'!T10 -> 4.125 | F14: ='2 Kitobcha (menejer)'!I81 -> 4.1 | G14: =IF(F14="","",F14-E14) -> -0.025 | H14: =IF(F14="","menejerda kg yo'q",IF(ABS(G14)>0.3,"farq katta","yaqin")) -> yaqin | I14: 11 | J14: 11 | K14: №77 bilan strelka orqali bog'langan
A15: Shashka | B15: 17 | C15: 101 | D15: Shashka | E15: ='1 Archive qoliplar'!T20 -> 4.18 | F15: ='2 Kitobcha (menejer)'!I104 -> 4.2 | G15: =IF(F15="","",F15-E15) -> 0.02 | H15: =IF(F15="","menejerda kg yo'q",IF(ABS(G15)>0.3,"farq katta","yaqin")) -> yaqin | I15: 11 | J15: 11
A16: Kabanchik 10×10 (kitayskiy) | B16: 23 | C16: 47 | D16: Kabanchik | E16: ='1 Archive qoliplar'!T26 -> 4.83 | F16: ='2 Kitobcha (menejer)'!I50 -> 6.1 | G16: =IF(F16="","",F16-E16) -> 1.27 | H16: =IF(F16="","menejerda kg yo'q",IF(ABS(G16)>0.3,"farq katta","yaqin")) -> farq katta | I16: 92 | J16: 50 | K16: Egasi tomonidan tasdiqlandi
A17: Parus 18×36 | B17: 39 | C17: 24 | D17: Parus | E17: ='1 Archive qoliplar'!T59 -> 5.17 | F17: ='2 Kitobcha (menejer)'!I27 -> 5.3 | G17: =IF(F17="","",F17-E17) -> 0.13 | H17: =IF(F17="","menejerda kg yo'q",IF(ABS(G17)>0.3,"farq katta","yaqin")) -> yaqin | I17: 14,5 + 14,5 | J17: 13,5 + 13,5 | K17: B qolip vazni va soni jami vaznga mos kelmaydi
A18: Vegas 1 (gladkiy) | B18: 36 | C18: 27 | D18: Vegas | E18: ='1 Archive qoliplar'!T51 -> 4.675 | F18: ='2 Kitobcha (menejer)'!I30 -> 4.9 | G18: =IF(F18="","",F18-E18) -> 0.225 | H18: =IF(F18="","menejerda kg yo'q",IF(ABS(G18)>0.3,"farq katta","yaqin")) -> yaqin | I18: 8,2 + 4,1 + 4,1 | J18: 8,2 + 4,2 + 4,2
A19: Kabanchik 17×17 (shershaviy) | B19: 38 | C19: 50 | D19: Kabanchik | E19: ='1 Archive qoliplar'!T57 -> 4.65 | F19: ='2 Kitobcha (menejer)'!I53 -> 5.2 | G19: =IF(F19="","",F19-E19) -> 0.55 | H19: =IF(F19="","menejerda kg yo'q",IF(ABS(G19)>0.3,"farq katta","yaqin")) -> farq katta | I19: 30 + 30 | J19: 33 + 33
A20: 3D Parus | B20: 59 | C20: 25 | D20: 3D | E20: ='1 Archive qoliplar'!T102 -> 4.925 | F20: ='2 Kitobcha (menejer)'!I28 -> 5.2 | G20: =IF(F20="","",F20-E20) -> 0.275 | H20: =IF(F20="","menejerda kg yo'q",IF(ABS(G20)>0.3,"farq katta","yaqin")) -> yaqin | I20: 8,2 + 16,4 | J20: 6,5 + 13 | K20: Jami vazn qismlar yig'indisidan kam
A21: 4D (shershaviy) | B21: 60 | C21: 26 | D21: 4D | E21: ='1 Archive qoliplar'!T104 -> 5.33 | F21: ='2 Kitobcha (menejer)'!I29 -> 5.8 | G21: =IF(F21="","",F21-E21) -> 0.47 | H21: =IF(F21="","menejerda kg yo'q",IF(ABS(G21)>0.3,"farq katta","yaqin")) -> farq katta | I21: 8,2 + 32,8 | J21: 8 + 32
A22: Dubay toshli (kamenniy) | B22: 66 | C22: 13 | D22: Dubay | E22: ='1 Archive qoliplar'!T112 -> 6.3 | F22: ='2 Kitobcha (menejer)'!I16 -> 6 | G22: =IF(F22="","",F22-E22) -> -0.3 | H22: =IF(F22="","menejerda kg yo'q",IF(ABS(G22)>0.3,"farq katta","yaqin")) -> yaqin | I22: 21 | J22: 21 qolip | K22: "42 uzunligi, 12 eni"; Uch katak kvadrat qilib yozilgan
A23: Dubay g'adir-budur (shershaviy) | B23: 68 | C23: 29 | D23: Dubay shershavoe | E23: ='1 Archive qoliplar'!T114 -> 6.3 | F23: ='2 Kitobcha (menejer)'!I32 -> 6 | G23: =IF(F23="","",F23-E23) -> -0.3 | H23: =IF(F23="","menejerda kg yo'q",IF(ABS(G23)>0.3,"farq katta","yaqin")) -> yaqin | I23: 21 | J23: 21 | K23: Uch katak kvadrat qilib yozilgan
A24: Dubay yaltiroq (glyanets) | B24: 67 | C24: 32 | D24: Dubay gladkiy | E24: ='1 Archive qoliplar'!T113 -> 6.3 | F24: ='2 Kitobcha (menejer)'!I35 -> 6 | G24: =IF(F24="","",F24-E24) -> -0.3 | H24: =IF(F24="","menejerda kg yo'q",IF(ABS(G24)>0.3,"farq katta","yaqin")) -> yaqin | I24: 21 | J24: 21 | K24: Faqat pastdagi 3 katakli qolip — trapetsiya qoliplar kirmaydi (tasdiqlandi); Uch katak kvadrat qilib yozilgan
A25: Dubay aylana (okrujnost) | B25: 61 | C25: 30 | D25: Dubay | E25: ='1 Archive qoliplar'!T106 -> 6 | F25: ='2 Kitobcha (menejer)'!I33 -> 6.2 | G25: =IF(F25="","",F25-E25) -> 0.2 | H25: =IF(F25="","menejerda kg yo'q",IF(ABS(G25)>0.3,"farq katta","yaqin")) -> yaqin | I25: 45 + 45 | J25: 45 | K25: Yana ikki o'lcham yozilgan: 83×83×30 va 100×100×30 — qaysi qolipga tegishli ekani noma'lum
A26: Farovon | B26: 56 | C26: 33 | D26: Farovon | E26: ='1 Archive qoliplar'!T95 -> 5.55 | F26: ='2 Kitobcha (menejer)'!I36 -> 5.71 | G26: =IF(F26="","",F26-E26) -> 0.16 | H26: =IF(F26="","menejerda kg yo'q",IF(ABS(G26)>0.3,"farq katta","yaqin")) -> yaqin | I26: 15 + 15 | J26: 15 + 15 | K26: Egasi tomonidan tasdiqlandi; B qolip o'lchami 53×53 deb yozilgan — rasmda katta "H" shakl (xato bo'lishi mumkin)
A27: Royal 1 | B27: 54 | C27: 34 | D27: Royal 1 | E27: ='1 Archive qoliplar'!T90 -> 4.625 | F27: ='2 Kitobcha (menejer)'!I37 -> 4.5 | G27: =IF(F27="","",F27-E27) -> -0.125 | H27: =IF(F27="","menejerda kg yo'q",IF(ABS(G27)>0.3,"farq katta","yaqin")) -> yaqin | I27: 12,5 + 25 | J27: 25 + 12,5 | K27: Oldingi raqamlar o'chirib tuzatilgan
A28: Royal 2 | B28: 55 | C28: 35 | D28: Royal 2 | E28: ='1 Archive qoliplar'!T92 -> 5.3 | F28: ='2 Kitobcha (menejer)'!I38 -> 4.2 | G28: =IF(F28="","",F28-E28) -> -1.1 | H28: =IF(F28="","menejerda kg yo'q",IF(ABS(G28)>0.3,"farq katta","yaqin")) -> farq katta | I28: 6 + 22 + 6 | J28: 6 + 22 + 6 | K28: V qolip (kichik kvadrat) rasmda yo'q, faqat sxemada; vazn hisobi mos kelmaydi
A29: Vindovs | B29: 58 | C29: 36 | D29: Windows | E29: ='1 Archive qoliplar'!T99 -> 5.3 | F29: ='2 Kitobcha (menejer)'!I39 -> 4.56 | G29: =IF(F29="","",F29-E29) -> -0.74 | H29: =IF(F29="","menejerda kg yo'q",IF(ABS(G29)>0.3,"farq katta","yaqin")) -> farq katta | I29: 15 + 15 + 4 | J29: 4 + 15 + 15 | K29: V qolip vazni yozilmagan; jami mos kelmaydi
A30: Aziya 3 | B30: 53 | C30: 41 | D30: Aziya 3 | E30: ='1 Archive qoliplar'!T88 -> 4.84 | F30: ='2 Kitobcha (menejer)'!I44 -> 5.1 | G30: =IF(F30="","",F30-E30) -> 0.26 | H30: =IF(F30="","menejerda kg yo'q",IF(ABS(G30)>0.3,"farq katta","yaqin")) -> yaqin | I30: 11 + 5,5 | J30: 5,5 + 11
A31: Aziya | B31: 50 | C31: 42 | D31: Aziya | E31: ='1 Archive qoliplar'!T81 -> 5.225 | F31: ='2 Kitobcha (menejer)'!I45 -> 4.3 | G31: =IF(F31="","",F31-E31) -> -0.925 | H31: =IF(F31="","menejerda kg yo'q",IF(ABS(G31)>0.3,"farq katta","yaqin")) -> farq katta | I31: 22 + 11 | J31: 22 + 11
A32: Azaliya 1 | B32: 46 | C32: 61 | D32: Azaliya 1 | E32: ='1 Archive qoliplar'!T73 -> 5.04 | F32: ='2 Kitobcha (menejer)'!I64 -> 4.9 | G32: =IF(F32="","",F32-E32) -> -0.14 | H32: =IF(F32="","menejerda kg yo'q",IF(ABS(G32)>0.3,"farq katta","yaqin")) -> yaqin | I32: 12 + 12 | J32: 12 + 12
A33: Azaliya 2 | B33: 47 | C33: 62 | D33: Azaliya 2 | E33: ='1 Archive qoliplar'!T75 -> 5.04 | F33: ='2 Kitobcha (menejer)'!I65 -> 4.9 | G33: =IF(F33="","",F33-E33) -> -0.14 | H33: =IF(F33="","menejerda kg yo'q",IF(ABS(G33)>0.3,"farq katta","yaqin")) -> yaqin | I33: 12 + 12 | J33: 12 + 12 | K33: №61 bilan strelka orqali bog'langan
A34: Aziya 1 | B34: 51 | C34: 63 | D34: Aziya 1 | E34: ='1 Archive qoliplar'!T83 -> 4.485 | F34: ='2 Kitobcha (menejer)'!I66 -> 4.6 | G34: =IF(F34="","",F34-E34) -> 0.115 | H34: =IF(F34="","menejerda kg yo'q",IF(ABS(G34)>0.3,"farq katta","yaqin")) -> yaqin | I34: 12 + 3 | J34: 12 + 3
A35: Aziya 2 | B35: 52 | C35: 64 | D35: Aziya 2 | E35: ='1 Archive qoliplar'!T85 -> 4.71 | F35: ='2 Kitobcha (menejer)'!I67 -> 4.9 | G35: =IF(F35="","",F35-E35) -> 0.19 | H35: =IF(F35="","menejerda kg yo'q",IF(ABS(G35)>0.3,"farq katta","yaqin")) -> yaqin | I35: 3 + 3 + 12 | J35: 3 + 12 + 3 | K35: Uch qolip birga teriladi
A36: Afina | B36: 44 | C36: 66 | D36: Afina | E36: ='1 Archive qoliplar'!T69 -> 5.08 | F36: ='2 Kitobcha (menejer)'!I69 -> 4.6 | G36: =IF(F36="","",F36-E36) -> -0.48 | H36: =IF(F36="","menejerda kg yo'q",IF(ABS(G36)>0.3,"farq katta","yaqin")) -> farq katta | I36: 13 + 19 | J36: 19 + 13
A37: Buxoro | B37: 43 | C37: 67 | D37: Buxara | E37: ='1 Archive qoliplar'!T67 -> 5.04 | F37: ='2 Kitobcha (menejer)'!I70 -> 4.9 | G37: =IF(F37="","",F37-E37) -> -0.14 | H37: =IF(F37="","menejerda kg yo'q",IF(ABS(G37)>0.3,"farq katta","yaqin")) -> yaqin | I37: 9 + 18 | J37: 18 + 9
A38: Bumerang | B38: 63 | C38: 68 | D38: Bumerang | E38: ='1 Archive qoliplar'!T109 -> 6.11 | F38: ='2 Kitobcha (menejer)'!I71 -> 5.9 | G38: =IF(F38="","",F38-E38) -> -0.21 | H38: =IF(F38="","menejerda kg yo'q",IF(ABS(G38)>0.3,"farq katta","yaqin")) -> yaqin | I38: 47 | J38: 47
A39: Rombik eski (stariy) | B39: 64 | C39: 59 | D39: Rombik 1 | E39: ='1 Archive qoliplar'!T110 -> 4.05 | F39: ='2 Kitobcha (menejer)'!I62 -> 4 | G39: =IF(F39="","",F39-E39) -> -0.05 | H39: =IF(F39="","menejerda kg yo'q",IF(ABS(G39)>0.3,"farq katta","yaqin")) -> yaqin | I39: 30 | J39: 30
A40: Rombik yangi (noviy) | B40: 65 | C40: 60 | D40: Rombik 2 | E40: ='1 Archive qoliplar'!T111 -> 5.85 | F40: ='2 Kitobcha (menejer)'!I63 -> 6.4 | G40: =IF(F40="","",F40-E40) -> 0.55 | H40: =IF(F40="","menejerda kg yo'q",IF(ABS(G40)>0.3,"farq katta","yaqin")) -> farq katta | I40: 30 | K40: "6 kg 400"
...

Sheet 5 Surat-model
A1: Suratlarni modelga bog'lash — 264 ta surat
A2: Bog'lanish eski katalog va kitobcha rasmlari bilan yonma-yon solishtirib qilingan (mening taxminim). "Taxminiy" va "noma'lum" qatorlarni menejer bilan tekshirish kerak.
A3: Surat (DSC) | B3: Guruh | C3: Taxminiy model | D3: Izoh | E3: Ishonch
A4: DSC03281 | B4: Plitka qolipi | C4: Fasad qolipi (kapitel / baza turi) | D4: Och rangli; nomi va o'lchami kerak | E4: noma'lum — nomi kerak
A5: DSC03282 | B5: Plitka qolipi | C5: Kerpich 10×20×7 (№80) | D5: 2 katakli chuqur qolip | E5: taxminiy
A6: DSC03283 | B6: Plitka qolipi | C6: Aleya uzor — sakkiz qirra 27×27 (№56) | D6: 1-kadr | E6: ishonchli
A7: DSC03284 | B7: Plitka qolipi | C7: Aleya uzor — sakkiz qirra 27×27 (№56) | D7: 2-kadr | E7: ishonchli
A8: DSC03285 | B8: Plitka qolipi | C8: Aleya / Aleya 2 — sakkiz qirra (№48, №54) | D8: Asosiy qolip | E8: ishonchli
A9: DSC03286 | B9: Plitka qolipi | C9: Uzor 20×20 ×2 | D9: Asosiy qolip (gul naqshli) | E9: taxminiy
A10: DSC03287 | B10: Plitka qolipi | C10: Parket 12×36 (№89)? | D10: Uzun, tosh teksturali | E10: taxminiy
A11: DSC03288 | B11: Plitka qolipi | C11: Bodom 20×20 ×4 — asosiy | D11: Mayda tosh naqshli sakkiz qirra | E11: ishonchli
A12: DSC03289 | B12: Plitka qolipi | C12: Strelka (kitobchada №76 Plyus) | D12: Yakka kvadrat 30×30 | E12: ishonchli
A13: DSC03290 | B13: Plitka qolipi | C13: Travertino | D13: Yakka kvadrat 30×30 | E13: ishonchli
A14: DSC03291 | B14: Plitka qolipi | C14: Zanjir | D14: Yakka kvadrat 30×30 | E14: ishonchli
... A25: DSC03302 | B25: Plitka qolipi | C25: Farovon — asosiy | D25: 1-kadr | E25: ishonchli
A26: DSC03303 | B26: Plitka qolipi | C26: Royal 1 — asosiy | E26: ishonchli
A27: DSC03304 | B27: Plitka qolipi | C27: Ornament 30×30 (kitobchada National, №15 ning katta qolipi) | E27: ishonchli
A28: DSC03305 | B28: Plitka qolipi | C28: Ventilyator — katta qolip | E28: ishonchli
A29: DSC03306 | B29: Plitka qolipi | C29: Aziya 3 — asosiy | D29: 1-kadr | E29: ishonchli
A30: DSC03307 | B30: Plitka qolipi | C30: Rombik eski (kitobcha: Rombik 1) | E30: ishonchli
A31: DSC03308 | B31: Plitka qolipi | C31: Zina 30×30 (№100) | D31: Chuvalchang naqsh + zina chiziqlari | E31: ishonchli
A32: DSC03309 | B32: Plitka qolipi | C32: Travertin 40×40 (№49) | D32: Ko'p bo'lakli, tosh teksturali | E32: taxminiy
A33: DSC03310 | B33: Plitka qolipi | C33: Farovon — sherik ("H" shakl) | D33: 2-kadr | E33: ishonchli
A34: DSC03311 | B34: Plitka qolipi | C34: Ona-bola 1 — asosiy | D34: Kichik pog'onali xoch, gulli | E34: ishonchli
A35: DSC03312 | B35: Plitka qolipi | C35: Kabanchik 15×15 (2 katakli), silliq? | E35: taxminiy
A36: DSC03313 | B36: Plitka qolipi | C36: Kabanchik 15×15 (2 katakli, №6 / №23)? | D36: Tosh teksturali | E36: taxminiy
A37: DSC03314 | B37: Plitka qolipi | C37: Gladkiy 18×36 — asosiy | E37: ishonchli
A38: DSC03315 | B38: Plitka qolipi | C38: Nomi noma'lum | D38: Uzun qolip, o'rama naqshli | E38: noma'lum — nomi kerak
A39: DSC03316 | B39: Plitka qolipi | C39: Aleya uzor — sherik 13×13 (№56) yoki Azaliya 13×13 (№82) | D39: Kichik kvadrat, naqshli | E39: taxminiy
A40: DSC03317 | B40: Plitka qolipi | C40: Ornament 18×36 yoki Dojdik 18×36 — asosiy | E40: taxminiy
A41: DSC03318 | B41: Plitka qolipi | C41: 20×20 guruhi — nomi aniqlanmadi | D41: Kichikroq | E41: noma'lum — nomi kerak
A42: DSC03319 | B42: Plitka qolipi | C42: 20×20 guruhi — nomi aniqlanmadi | D42: Kichikroq, to'r naqshli | E42: noma'lum — nomi kerak
A43: DSC03320 | B43: Plitka qolipi | C43: Dubay aylana — 2 katakli trapetsiya | D43: Kichik | E43: ishonchli
A44: DSC03322 | B44: Plitka qolipi | C44: Zina 30×30 (№99) | D44: To'r naqsh + zina chiziqlari | E44: ishonchli
A45: DSC03323 | B45: Plitka qolipi | C45: Tsvetok (kitobchada №5 Uzor) | D45: Yakka kvadrat 30×30 | E45: ishonchli
A46: DSC03324 | B46: Plitka qolipi | C46: Aziya 3 — sherik (yulduz) | E46: ishonchli
A47: DSC03325 | B47: Plitka qolipi | C47: Ona-bola 1 — sherik (135 mm) | D47: To'rt yaproqli, tomchi gulbargli, kichik | E47: taxminiy
A48: DSC03326 | B48: Plitka qolipi | C48: Ona-bola 2 — sherik (135 mm) | D48: To'rt yaproqli, xoch naqshli, kichik | E48: taxminiy
A49: DSC03327 | B49: Plitka qolipi | C49: Bodom 20×20 ×2 — asosiy | D49: Mayda tosh naqshli | E49: taxminiy
A50: DSC03328 | B50: Plitka qolipi | C50: Xokkey (№73) | D50: Bumerang emas — Bumerang surati topilmadi | E50: ishonchli
...

Sheet 6 SPS PLAST termopanel
A1: SPS PLAST fasad termopanel katalogi (2026–2027) — 76 ta mahsulot
A2: Manba: Archive.zip dagi fasad katalogi. Ranglar: Travertinoviy / Mramorniy; asos: Penoplast (TP guruhida Bazalt ham).
A3: Kod | B3: Nomi (katalogdagi sarlavha) | C3: O'lcham, mm | D3: Bet | E3: Izoh
A4: TP-001 | B4: 30×60 Kirpich | C4: 300×600 | D4: 10–11
A5: TP-002 | B5: 30×60 Gladkiy | C5: 300×600 | D5: 10–11
A6: TP-003 | B6: 30×60 Beeline | C6: 300×600 | D6: 10–11
A7: TP-004 | B7: 30×60 Kuba | C7: 300×600 | D7: 10–11
A8: TP-005 | B8: 25×50 Pryamaya | C8: 250×500 | D8: 12–13
A9: TP-006 | B9: 25×50 Kruglaya | C9: 250×500 | D9: 12–13
A10: TP-007 | B10: 25×50 Kirpich | C10: 250×500 | D10: 12–13
A11: TP-008 | B11: 25×50 3D | C11: 250×500 | D11: 12–13
A12: TP-009 | B12: 25×50 Brilliant | C12: 250×500 | D12: 14–15
A13: TP-010 | B13: 25×50 Beeline | C13: 250×500 | D13: 14–15
A14: TP-011 | B14: 20×40 Pryamaya | C14: 250×500 | D14: 14–15 | E14: Sarlavhada 20×40, o'lcham katagida 250×500
A15: TP-012 | B15: 25×50 Labirint | C15: 250×500 | D15: 14–15
A16: FSD-001 | B16: 120×40 Dekor 1 | C16: 400×1200 | D16: 16–19
A17: FSD-002 | B17: 120×40 Dekor 2 | C17: 400×1200 | D17: 16–19
A18: FSD-003 | B18: 120×40 Dekor 3 | C18: 400×1200 | D18: 16–19
A19: FSD-004 | B19: 120×40 Dekor 4 | C19: 400×1200 | D19: 16–19
A20: FSD-005 | B20: 120×40 Dekor 5 | C20: 400×1200 | D20: 16–19
A21: FSD-006 | B21: 120×40 Dekor 6 | C21: 400×1200 | D21: 16–19
A22: FSD-007 | B22: 120×40 Dekor 7 | C22: 400×1200 | D22: 16–19
A23: FSD-008 | B23: 120×40 Dekor 8 | C23: 400×1200 | D23: 16–19
A24: FSD-009 | B24: 100×50 Dekor 1 | C24: 500×1000 | D24: 20–21
A25: FSD-010 | B25: 100×50 Dekor 2 | C25: 500×1000 | D25: 20–21
A26: FSD-011 | B26: 100×50 Dekor 3 | C26: 500×1000 | D26: 20–21
... A38: NL-003 | B38: 15×120 Tyaga | C38: 150×1200 | D38: 26–27
A39: KRN-004 | B39: 18×120 Karniz | C39: 180×1200 | D39: 26–27 | E39: KRN-004 kodi ikki marta ishlatilgan
A40: KRN-001 | B40: 18×120 Karniz | C40: 180×1200 | D40: 28–29
A41: KRN-002 | B41: 18×120 Karniz | C41: 180×1200 | D41: 28–29
A42: KRN-003 | B42: 18×120 Karniz | C42: 180×1200 | D42: 28–29
A43: KRN-004 | B43: 35×120 Karniz | C43: 350×1200 | D43: 28–29 | E43: KRN-004 kodi ikki marta ishlatilgan
A44: KRN-005 | B44: 35×120 Karniz | C44: 350×1200 | D44: 30–31
A45: KRN-006 | B45: 50×120 Karniz | C45: 500×1200 | D45: 30–31
A46: KRN-007 | B46: 35×120 Karniz | C46: 350×1200 | D46: 30–31
A47: KRN-008 | B47: 30×120 Karniz | C47: 300×1200 | D47: 30–31
A48: KRN-009 | B48: 25×120 Karniz | C48: 250×1200 | D48: 32–33
A49: KRN-010 | B49: 20×120 Karniz | C49: 200×1200 | D49: 32–33
A50: PL-002 | B50: 40×120 Pilyastra | C50: 400×1200 | D50: 32–33 | E50: PL-001 katalogda yo'q
A51: PL-003 | B51: 40×120 Pilyastra | C51: 400×1200 | D51: 32–33
...
